my_type=hypothesis
proj=hdfs
u_test=org.apache.hadoop.hdfs.server.datanode.TestDataNodeVolumeFailureReporting#testSuccessiveVolumeFailures
h_list[1]=dfs.datanode.du.reserved@@@hdfs:DataNode@@@-2@@@16384@@@0
proj: hdfs
u_test: org.apache.hadoop.hdfs.server.datanode.TestDataNodeVolumeFailureReporting#testSuccessiveVolumeFailures
h_list: dfs.datanode.du.reserved@@@hdfs:DataNode@@@-2@@@16384@@@0
updating test result for file org.apache.hadoop.hdfs.server.datanode.TestDataNodeVolumeFailureReporting#testSuccessiveVolumeFailures
v1v2 running time = 21245259191
---> v1v2 test failed.
proj: hdfs
u_test: org.apache.hadoop.hdfs.server.datanode.TestDataNodeVolumeFailureReporting#testSuccessiveVolumeFailures
h_list: dfs.datanode.du.reserved@@@hdfs:DataNode@@@-2@@@16384@@@0
vv_mode: v1v2
result: FAIL
failureMessage: expected:<449179320320> but was:<449179336704>
stackTrace: java.lang.AssertionError: expected:<449179320320> but was:<449179336704>
	at org.junit.Assert.fail(Assert.java:88)
	at org.junit.Assert.failNotEquals(Assert.java:834)
	at org.junit.Assert.assertEquals(Assert.java:645)
	at org.junit.Assert.assertEquals(Assert.java:631)
	at org.apache.hadoop.hdfs.server.datanode.TestDataNodeVolumeFailureReporting.checkFailuresAtDataNode(TestDataNodeVolumeFailureReporting.java:671)
	at org.apache.hadoop.hdfs.server.datanode.TestDataNodeVolumeFailureReporting.testSuccessiveVolumeFailures(TestDataNodeVolumeFailureReporting.java:167)
	at sun.reflect.NativeMethodAccessorImpl.invoke0(Native Method)
	at sun.reflect.NativeMethodAccessorImpl.invoke(NativeMethodAccessorImpl.java:62)
	at sun.reflect.DelegatingMethodAccessorImpl.invoke(DelegatingMethodAccessorImpl.java:43)
	at java.lang.reflect.Method.invoke(Method.java:498)
	at org.junit.runners.model.FrameworkMethod$1.runReflectiveCall(FrameworkMethod.java:50)
	at org.junit.internal.runners.model.ReflectiveCallable.run(ReflectiveCallable.java:12)
	at org.junit.runners.model.FrameworkMethod.invokeExplosively(FrameworkMethod.java:47)
	at org.junit.internal.runners.statements.InvokeMethod.evaluate(InvokeMethod.java:17)
	at org.junit.internal.runners.statements.RunBefores.evaluate(RunBefores.java:26)
	at org.junit.internal.runners.statements.RunAfters.evaluate(RunAfters.java:27)
	at org.junit.internal.runners.statements.FailOnTimeout$CallableStatement.call(FailOnTimeout.java:298)
	at org.junit.internal.runners.statements.FailOnTimeout$CallableStatement.call(FailOnTimeout.java:292)
	at java.util.concurrent.FutureTask.run(FutureTask.java:266)
	at java.lang.Thread.run(Thread.java:748)


updating test result for file org.apache.hadoop.hdfs.server.datanode.TestDataNodeVolumeFailureReporting#testSuccessiveVolumeFailures
v1v1 running time = 45525469838
updating test result for file org.apache.hadoop.hdfs.server.datanode.TestDataNodeVolumeFailureReporting#testSuccessiveVolumeFailures
v2v2 running time = 44130007918
---> v1v1 and v2v2 test test suceeded.
updating test result for file org.apache.hadoop.hdfs.server.datanode.TestDataNodeVolumeFailureReporting#testSuccessiveVolumeFailures
v1v2 running time = 19294664426
---> v1v2 test failed.
proj: hdfs
u_test: org.apache.hadoop.hdfs.server.datanode.TestDataNodeVolumeFailureReporting#testSuccessiveVolumeFailures
h_list: dfs.datanode.du.reserved@@@hdfs:DataNode@@@-2@@@16384@@@0
vv_mode: v1v2
result: FAIL
failureMessage: expected:<449179320320> but was:<449179336704>
stackTrace: java.lang.AssertionError: expected:<449179320320> but was:<449179336704>
	at org.junit.Assert.fail(Assert.java:88)
	at org.junit.Assert.failNotEquals(Assert.java:834)
	at org.junit.Assert.assertEquals(Assert.java:645)
	at org.junit.Assert.assertEquals(Assert.java:631)
	at org.apache.hadoop.hdfs.server.datanode.TestDataNodeVolumeFailureReporting.checkFailuresAtDataNode(TestDataNodeVolumeFailureReporting.java:671)
	at org.apache.hadoop.hdfs.server.datanode.TestDataNodeVolumeFailureReporting.testSuccessiveVolumeFailures(TestDataNodeVolumeFailureReporting.java:167)
	at sun.reflect.NativeMethodAccessorImpl.invoke0(Native Method)
	at sun.reflect.NativeMethodAccessorImpl.invoke(NativeMethodAccessorImpl.java:62)
	at sun.reflect.DelegatingMethodAccessorImpl.invoke(DelegatingMethodAccessorImpl.java:43)
	at java.lang.reflect.Method.invoke(Method.java:498)
	at org.junit.runners.model.FrameworkMethod$1.runReflectiveCall(FrameworkMethod.java:50)
	at org.junit.internal.runners.model.ReflectiveCallable.run(ReflectiveCallable.java:12)
	at org.junit.runners.model.FrameworkMethod.invokeExplosively(FrameworkMethod.java:47)
	at org.junit.internal.runners.statements.InvokeMethod.evaluate(InvokeMethod.java:17)
	at org.junit.internal.runners.statements.RunBefores.evaluate(RunBefores.java:26)
	at org.junit.internal.runners.statements.RunAfters.evaluate(RunAfters.java:27)
	at org.junit.internal.runners.statements.FailOnTimeout$CallableStatement.call(FailOnTimeout.java:298)
	at org.junit.internal.runners.statements.FailOnTimeout$CallableStatement.call(FailOnTimeout.java:292)
	at java.util.concurrent.FutureTask.run(FutureTask.java:266)
	at java.lang.Thread.run(Thread.java:748)


updating test result for file org.apache.hadoop.hdfs.server.datanode.TestDataNodeVolumeFailureReporting#testSuccessiveVolumeFailures
v1v1 running time = 45615557007
updating test result for file org.apache.hadoop.hdfs.server.datanode.TestDataNodeVolumeFailureReporting#testSuccessiveVolumeFailures
v2v2 running time = 43792097737
---> v1v1 and v2v2 test test suceeded.
updating test result for file org.apache.hadoop.hdfs.server.datanode.TestDataNodeVolumeFailureReporting#testSuccessiveVolumeFailures
v1v2 running time = 17986804930
---> v1v2 test failed.
proj: hdfs
u_test: org.apache.hadoop.hdfs.server.datanode.TestDataNodeVolumeFailureReporting#testSuccessiveVolumeFailures
h_list: dfs.datanode.du.reserved@@@hdfs:DataNode@@@-2@@@16384@@@0
vv_mode: v1v2
result: FAIL
failureMessage: expected:<449179320320> but was:<449179336704>
stackTrace: java.lang.AssertionError: expected:<449179320320> but was:<449179336704>
	at org.junit.Assert.fail(Assert.java:88)
	at org.junit.Assert.failNotEquals(Assert.java:834)
	at org.junit.Assert.assertEquals(Assert.java:645)
	at org.junit.Assert.assertEquals(Assert.java:631)
	at org.apache.hadoop.hdfs.server.datanode.TestDataNodeVolumeFailureReporting.checkFailuresAtDataNode(TestDataNodeVolumeFailureReporting.java:671)
	at org.apache.hadoop.hdfs.server.datanode.TestDataNodeVolumeFailureReporting.testSuccessiveVolumeFailures(TestDataNodeVolumeFailureReporting.java:167)
	at sun.reflect.NativeMethodAccessorImpl.invoke0(Native Method)
	at sun.reflect.NativeMethodAccessorImpl.invoke(NativeMethodAccessorImpl.java:62)
	at sun.reflect.DelegatingMethodAccessorImpl.invoke(DelegatingMethodAccessorImpl.java:43)
	at java.lang.reflect.Method.invoke(Method.java:498)
	at org.junit.runners.model.FrameworkMethod$1.runReflectiveCall(FrameworkMethod.java:50)
	at org.junit.internal.runners.model.ReflectiveCallable.run(ReflectiveCallable.java:12)
	at org.junit.runners.model.FrameworkMethod.invokeExplosively(FrameworkMethod.java:47)
	at org.junit.internal.runners.statements.InvokeMethod.evaluate(InvokeMethod.java:17)
	at org.junit.internal.runners.statements.RunBefores.evaluate(RunBefores.java:26)
	at org.junit.internal.runners.statements.RunAfters.evaluate(RunAfters.java:27)
	at org.junit.internal.runners.statements.FailOnTimeout$CallableStatement.call(FailOnTimeout.java:298)
	at org.junit.internal.runners.statements.FailOnTimeout$CallableStatement.call(FailOnTimeout.java:292)
	at java.util.concurrent.FutureTask.run(FutureTask.java:266)
	at java.lang.Thread.run(Thread.java:748)


updating test result for file org.apache.hadoop.hdfs.server.datanode.TestDataNodeVolumeFailureReporting#testSuccessiveVolumeFailures
v1v1 running time = 44570585999
updating test result for file org.apache.hadoop.hdfs.server.datanode.TestDataNodeVolumeFailureReporting#testSuccessiveVolumeFailures
v2v2 running time = 45192773359
---> v1v1 and v2v2 test test suceeded.
updating test result for file org.apache.hadoop.hdfs.server.datanode.TestDataNodeVolumeFailureReporting#testSuccessiveVolumeFailures
v1v2 running time = 17857111295
---> v1v2 test failed.
proj: hdfs
u_test: org.apache.hadoop.hdfs.server.datanode.TestDataNodeVolumeFailureReporting#testSuccessiveVolumeFailures
h_list: dfs.datanode.du.reserved@@@hdfs:DataNode@@@-2@@@16384@@@0
vv_mode: v1v2
result: FAIL
failureMessage: expected:<449179320320> but was:<449179336704>
stackTrace: java.lang.AssertionError: expected:<449179320320> but was:<449179336704>
	at org.junit.Assert.fail(Assert.java:88)
	at org.junit.Assert.failNotEquals(Assert.java:834)
	at org.junit.Assert.assertEquals(Assert.java:645)
	at org.junit.Assert.assertEquals(Assert.java:631)
	at org.apache.hadoop.hdfs.server.datanode.TestDataNodeVolumeFailureReporting.checkFailuresAtDataNode(TestDataNodeVolumeFailureReporting.java:671)
	at org.apache.hadoop.hdfs.server.datanode.TestDataNodeVolumeFailureReporting.testSuccessiveVolumeFailures(TestDataNodeVolumeFailureReporting.java:167)
	at sun.reflect.NativeMethodAccessorImpl.invoke0(Native Method)
	at sun.reflect.NativeMethodAccessorImpl.invoke(NativeMethodAccessorImpl.java:62)
	at sun.reflect.DelegatingMethodAccessorImpl.invoke(DelegatingMethodAccessorImpl.java:43)
	at java.lang.reflect.Method.invoke(Method.java:498)
	at org.junit.runners.model.FrameworkMethod$1.runReflectiveCall(FrameworkMethod.java:50)
	at org.junit.internal.runners.model.ReflectiveCallable.run(ReflectiveCallable.java:12)
	at org.junit.runners.model.FrameworkMethod.invokeExplosively(FrameworkMethod.java:47)
	at org.junit.internal.runners.statements.InvokeMethod.evaluate(InvokeMethod.java:17)
	at org.junit.internal.runners.statements.RunBefores.evaluate(RunBefores.java:26)
	at org.junit.internal.runners.statements.RunAfters.evaluate(RunAfters.java:27)
	at org.junit.internal.runners.statements.FailOnTimeout$CallableStatement.call(FailOnTimeout.java:298)
	at org.junit.internal.runners.statements.FailOnTimeout$CallableStatement.call(FailOnTimeout.java:292)
	at java.util.concurrent.FutureTask.run(FutureTask.java:266)
	at java.lang.Thread.run(Thread.java:748)


updating test result for file org.apache.hadoop.hdfs.server.datanode.TestDataNodeVolumeFailureReporting#testSuccessiveVolumeFailures
v1v1 running time = 45459832422
updating test result for file org.apache.hadoop.hdfs.server.datanode.TestDataNodeVolumeFailureReporting#testSuccessiveVolumeFailures
v2v2 running time = 46791549291
---> v1v1 and v2v2 test test suceeded.
updating test result for file org.apache.hadoop.hdfs.server.datanode.TestDataNodeVolumeFailureReporting#testSuccessiveVolumeFailures
v1v2 running time = 18879582717
---> v1v2 test failed.
proj: hdfs
u_test: org.apache.hadoop.hdfs.server.datanode.TestDataNodeVolumeFailureReporting#testSuccessiveVolumeFailures
h_list: dfs.datanode.du.reserved@@@hdfs:DataNode@@@-2@@@16384@@@0
vv_mode: v1v2
result: FAIL
failureMessage: expected:<449179320320> but was:<449179336704>
stackTrace: java.lang.AssertionError: expected:<449179320320> but was:<449179336704>
	at org.junit.Assert.fail(Assert.java:88)
	at org.junit.Assert.failNotEquals(Assert.java:834)
	at org.junit.Assert.assertEquals(Assert.java:645)
	at org.junit.Assert.assertEquals(Assert.java:631)
	at org.apache.hadoop.hdfs.server.datanode.TestDataNodeVolumeFailureReporting.checkFailuresAtDataNode(TestDataNodeVolumeFailureReporting.java:671)
	at org.apache.hadoop.hdfs.server.datanode.TestDataNodeVolumeFailureReporting.testSuccessiveVolumeFailures(TestDataNodeVolumeFailureReporting.java:167)
	at sun.reflect.NativeMethodAccessorImpl.invoke0(Native Method)
	at sun.reflect.NativeMethodAccessorImpl.invoke(NativeMethodAccessorImpl.java:62)
	at sun.reflect.DelegatingMethodAccessorImpl.invoke(DelegatingMethodAccessorImpl.java:43)
	at java.lang.reflect.Method.invoke(Method.java:498)
	at org.junit.runners.model.FrameworkMethod$1.runReflectiveCall(FrameworkMethod.java:50)
	at org.junit.internal.runners.model.ReflectiveCallable.run(ReflectiveCallable.java:12)
	at org.junit.runners.model.FrameworkMethod.invokeExplosively(FrameworkMethod.java:47)
	at org.junit.internal.runners.statements.InvokeMethod.evaluate(InvokeMethod.java:17)
	at org.junit.internal.runners.statements.RunBefores.evaluate(RunBefores.java:26)
	at org.junit.internal.runners.statements.RunAfters.evaluate(RunAfters.java:27)
	at org.junit.internal.runners.statements.FailOnTimeout$CallableStatement.call(FailOnTimeout.java:298)
	at org.junit.internal.runners.statements.FailOnTimeout$CallableStatement.call(FailOnTimeout.java:292)
	at java.util.concurrent.FutureTask.run(FutureTask.java:266)
	at java.lang.Thread.run(Thread.java:748)


updating test result for file org.apache.hadoop.hdfs.server.datanode.TestDataNodeVolumeFailureReporting#testSuccessiveVolumeFailures
v1v1 running time = 49898976690
updating test result for file org.apache.hadoop.hdfs.server.datanode.TestDataNodeVolumeFailureReporting#testSuccessiveVolumeFailures
v2v2 running time = 45739002484
---> v1v1 and v2v2 test test suceeded.
updating test result for file org.apache.hadoop.hdfs.server.datanode.TestDataNodeVolumeFailureReporting#testSuccessiveVolumeFailures
v1v2 running time = 17444388142
---> v1v2 test failed.
proj: hdfs
u_test: org.apache.hadoop.hdfs.server.datanode.TestDataNodeVolumeFailureReporting#testSuccessiveVolumeFailures
h_list: dfs.datanode.du.reserved@@@hdfs:DataNode@@@-2@@@16384@@@0
vv_mode: v1v2
result: FAIL
failureMessage: expected:<449179320320> but was:<449179336704>
stackTrace: java.lang.AssertionError: expected:<449179320320> but was:<449179336704>
	at org.junit.Assert.fail(Assert.java:88)
	at org.junit.Assert.failNotEquals(Assert.java:834)
	at org.junit.Assert.assertEquals(Assert.java:645)
	at org.junit.Assert.assertEquals(Assert.java:631)
	at org.apache.hadoop.hdfs.server.datanode.TestDataNodeVolumeFailureReporting.checkFailuresAtDataNode(TestDataNodeVolumeFailureReporting.java:671)
	at org.apache.hadoop.hdfs.server.datanode.TestDataNodeVolumeFailureReporting.testSuccessiveVolumeFailures(TestDataNodeVolumeFailureReporting.java:167)
	at sun.reflect.NativeMethodAccessorImpl.invoke0(Native Method)
	at sun.reflect.NativeMethodAccessorImpl.invoke(NativeMethodAccessorImpl.java:62)
	at sun.reflect.DelegatingMethodAccessorImpl.invoke(DelegatingMethodAccessorImpl.java:43)
	at java.lang.reflect.Method.invoke(Method.java:498)
	at org.junit.runners.model.FrameworkMethod$1.runReflectiveCall(FrameworkMethod.java:50)
	at org.junit.internal.runners.model.ReflectiveCallable.run(ReflectiveCallable.java:12)
	at org.junit.runners.model.FrameworkMethod.invokeExplosively(FrameworkMethod.java:47)
	at org.junit.internal.runners.statements.InvokeMethod.evaluate(InvokeMethod.java:17)
	at org.junit.internal.runners.statements.RunBefores.evaluate(RunBefores.java:26)
	at org.junit.internal.runners.statements.RunAfters.evaluate(RunAfters.java:27)
	at org.junit.internal.runners.statements.FailOnTimeout$CallableStatement.call(FailOnTimeout.java:298)
	at org.junit.internal.runners.statements.FailOnTimeout$CallableStatement.call(FailOnTimeout.java:292)
	at java.util.concurrent.FutureTask.run(FutureTask.java:266)
	at java.lang.Thread.run(Thread.java:748)


updating test result for file org.apache.hadoop.hdfs.server.datanode.TestDataNodeVolumeFailureReporting#testSuccessiveVolumeFailures
v1v1 running time = 45070753109
updating test result for file org.apache.hadoop.hdfs.server.datanode.TestDataNodeVolumeFailureReporting#testSuccessiveVolumeFailures
v2v2 running time = 44863981109
---> v1v1 and v2v2 test test suceeded.
updating test result for file org.apache.hadoop.hdfs.server.datanode.TestDataNodeVolumeFailureReporting#testSuccessiveVolumeFailures
v1v2 running time = 17152858798
---> v1v2 test failed.
proj: hdfs
u_test: org.apache.hadoop.hdfs.server.datanode.TestDataNodeVolumeFailureReporting#testSuccessiveVolumeFailures
h_list: dfs.datanode.du.reserved@@@hdfs:DataNode@@@-2@@@16384@@@0
vv_mode: v1v2
result: FAIL
failureMessage: expected:<449179320320> but was:<449179336704>
stackTrace: java.lang.AssertionError: expected:<449179320320> but was:<449179336704>
	at org.junit.Assert.fail(Assert.java:88)
	at org.junit.Assert.failNotEquals(Assert.java:834)
	at org.junit.Assert.assertEquals(Assert.java:645)
	at org.junit.Assert.assertEquals(Assert.java:631)
	at org.apache.hadoop.hdfs.server.datanode.TestDataNodeVolumeFailureReporting.checkFailuresAtDataNode(TestDataNodeVolumeFailureReporting.java:671)
	at org.apache.hadoop.hdfs.server.datanode.TestDataNodeVolumeFailureReporting.testSuccessiveVolumeFailures(TestDataNodeVolumeFailureReporting.java:167)
	at sun.reflect.NativeMethodAccessorImpl.invoke0(Native Method)
	at sun.reflect.NativeMethodAccessorImpl.invoke(NativeMethodAccessorImpl.java:62)
	at sun.reflect.DelegatingMethodAccessorImpl.invoke(DelegatingMethodAccessorImpl.java:43)
	at java.lang.reflect.Method.invoke(Method.java:498)
	at org.junit.runners.model.FrameworkMethod$1.runReflectiveCall(FrameworkMethod.java:50)
	at org.junit.internal.runners.model.ReflectiveCallable.run(ReflectiveCallable.java:12)
	at org.junit.runners.model.FrameworkMethod.invokeExplosively(FrameworkMethod.java:47)
	at org.junit.internal.runners.statements.InvokeMethod.evaluate(InvokeMethod.java:17)
	at org.junit.internal.runners.statements.RunBefores.evaluate(RunBefores.java:26)
	at org.junit.internal.runners.statements.RunAfters.evaluate(RunAfters.java:27)
	at org.junit.internal.runners.statements.FailOnTimeout$CallableStatement.call(FailOnTimeout.java:298)
	at org.junit.internal.runners.statements.FailOnTimeout$CallableStatement.call(FailOnTimeout.java:292)
	at java.util.concurrent.FutureTask.run(FutureTask.java:266)
	at java.lang.Thread.run(Thread.java:748)


updating test result for file org.apache.hadoop.hdfs.server.datanode.TestDataNodeVolumeFailureReporting#testSuccessiveVolumeFailures
v1v1 running time = 45385776280
updating test result for file org.apache.hadoop.hdfs.server.datanode.TestDataNodeVolumeFailureReporting#testSuccessiveVolumeFailures
v2v2 running time = 44566936910
---> v1v1 and v2v2 test test suceeded.
early stop after 7 is satisfied
v1v2 failed with probability 7 out of 7
v1v1v2v2 failed with probability 0 out of 7
Total execution time in seconds : 766
0
